<mujoco>
    <compiler angle="degree"/>
    <option gravity="0 0 -9.81"/>
    <asset/>
    <worldbody>
        <body name="base_link">
            <inertial diaginertia="0.01 0.01 0.01" mass="1" pos="0 0 0"/>
            <geom size="0.5 0.25 0.15" type="box"/>
            <body name="arm_link" pos="0.3 0 0.15">
                <inertial diaginertia="0.01 0.01 0.01" mass="0.5" pos="0 0 0.3"/>
                <geom pos="0 0 0.3" size="0.05 0.3 0.001" type="cylinder"/>
                <joint axis="0 1 0" name="arm_joint" range="-1.57 1.57" type="hinge"/>
            </body>
        </body>
    </worldbody>
    <actuator/>
    <sensor/>
    <equality/>
    <tendon/>
</mujoco>
